Workbook
Name Display_Week: 'Project Alpha LV Tracker'!$K$5
Name Display_Week: #REF!
Name Project_Start: 'Project Alpha LV Tracker'!$K$4
Name Project_Start: #REF!
Name task_end: 'Project Alpha LV Tracker'!$L1
Name task_progress: 'Project Alpha LV Tracker'!$I1
Name task_start: 'Project Alpha LV Tracker'!$K1
Name today: TODAY()

Sheet RESA XFMR Test Results
CV1: www.resapower.com
A7: MV XFMR TEST RESULT SUMMARY | CP7: TF-03 Rev.8
A9: JOB NUMBER: | S9: 559082 | AE9: DATE: | AS9: 45668 | BG9: TESTING STANDARD | CN9: P | CQ9: ACCEPTANCE TEST
A10: CLIENT NAME: | S10: STURGEON ELECTRIC | AE10: TESTED BY: | AS10: AP/TD | CQ10: MAINTENANCE TEST
A11: SITE/LOCATION: | S11: TPG CAT MODERNIZATION | AE11: APPROVED BY: | AS11: J. SWENSON | CQ11: PROOF TEST
B13: DEVICE ID | I13: RATING IN KVA | P13: SERIAL NUMBER | W13: POWER FACTOR | AD13: EXCITATION | AK13: INSULATION RESISTANCE | AR13: TURNS RATIO | AY13: WINDING RESISTANCE | BF13: BUSHINGS & ARRESTERS | BM13: CURRENT TRANSFORMER | CM13: OIL ANALYSIS | CR13: NOTES
CV56: www.resapower.com
A62: MV XFMR TEST RESULT SUMMARY | CP62: TF-03 Rev.8
A64: JOB NUMBER: | S64: 559082 | AE64: DATE: | AS64: 45668 | BG64: TESTING STANDARD | CN64: P | CQ64: ACCEPTANCE TEST
A65: CLIENT NAME: | S65: STURGEON ELECTRIC | AE65: TESTED BY: | AS65: AP/TD | CQ65: MAINTENANCE TEST
A66: SITE/LOCATION: | S66: TPG CAT MODERNIZATION | AE66: APPROVED BY: | AS66: J. SWENSON | CQ66: PROOF TEST
B68: DEVICE ID | I68: RATING IN KVA | P68: SERIAL NUMBER | W68: POWER FACTOR | AD68: EXCITATION | AK68: INSULATION RESISTANCE | AR68: TURNS RATIO | AY68: WINDING RESISTANCE | BF68: BUSHINGS & ARRESTERS | BM68: CURRENT TRANSFORMER | CM68: OIL ANALYSIS | CR68: NOTES

Sheet RESA MV Cable Test Results
CV1: www.resapower.com
A7: MV CABLE TEST RESULT SUMMARY | CP7: TF-03 Rev.8
A9: JOB NUMBER: | S9: 559082 | AE9: DATE: | AS9: 45678 | BG9: TESTING STANDARD | CN9: P | CQ9: ACCEPTANCE TEST
A10: CLIENT NAME: | S10: STURGEON ELECTRIC | AE10: TESTED BY: | AS10: AP/TD | CQ10: MAINTENANCE TEST
A11: SITE/LOCATION: | S11: TPG CAT MODERNIZATION | AE11: APPROVED BY: | AS11: J. SWENSON | CQ11: PROOF TEST
B13: CABLE ID | I13: LENGTH | P13: TYPE/INSULATION | W13: RATED VOLTAGE | AD13: SIZE | AK13: FORMATION | AR13: SOURCE LOCATION | AY13: TERMINATION LOCATION | BF13: INSULATION RESISTANCE | BM13: VLF | CM13: NOTES
CV56: www.resapower.com
A62: MV CABLE TEST RESULT SUMMARY | CP62: TF-03 Rev.8
A64: JOB NUMBER: | S64: 559082 | AE64: DATE: | AS64: 45678 | BG64: TESTING STANDARD | CN64: P | CQ64: ACCEPTANCE TEST
A65: CLIENT NAME: | S65: STURGEON ELECTRIC | AE65: TESTED BY: | AS65: AP/TD | CQ65: MAINTENANCE TEST
A66: SITE/LOCATION: | S66: TPG CAT MODERNIZATION | AE66: APPROVED BY: | AS66: J. SWENSON | CQ66: PROOF TEST
B68: CABLE ID | I68: LENGTH | P68: TYPE/INSULATION | W68: RATED VOLTAGE | AD68: SIZE | AK68: FORMATION | AR68: SOURCE LOCATION | AY68: TERMINATION LOCATION | BF68: INSULATION RESISTANCE | BM68: VLF | CM68: NOTES
A112: ACCEPTABLE
A113: NOT ACCEPTABLE
A114: SEE NOTES

Sheet Project Alpha LV Tracker
A2: Create a Project Schedule in this worksheet. Enter title of this project in cell B1. Information about how to use this worksheet, including instructions for screen readers and the author of this workbook is in the About worksheet. Continue navigating down column A to hear further instructions. | B2: Project Alpha:
B3: RESA Power Project Manager: Jason Swenson
A4: Enter the name of the Project Lead in cell B3. Enter the Project Start date in cell E3. Project Start: label is in cell C3. | B4: RESA Power Lead Technician: Austin Painter | D4: Project Start: | K4: 45839
A5: The Display Week in cell E4 represents the starting week to display in the project schedule in cell I4. The project start date is considered Week 1. To change the display week, simply enter a new week number in cell E4. The starting date for each week, starting with the display week from cell E4, starts in cell I4 and is auto calculated. There are 8 weeks represented in this view from cell I4 through cell BF4. You should not modify these cells. Display Week: label is in cell C4. | B5: 45894 | D5: Display Week: | K5: 3 | O5: =O6 -> 45852 | V5: =V6 -> 45859 | AC5: =AC6 -> 45866 | AJ5: =AJ6 -> 45873 | AQ5: =AQ6 -> 45880 | AX5: =AX6 -> 45887 | BE5: =BE6 -> 45894 | BL5: =BL6 -> 45901
A6: Cells I5 through BL5 contain the day number for the week represented in the cell block above each date cell and are auto calculated. You should not modify these cells. Today's date is outlined in Red (hex #AD3815) from today's date in row 5 through the entire date column to the end of the project schedule. | O6: =Project_Start-WEEKDAY(Project_Start,1)+2+7*(Display_Week-1) -> 45852 | P6: =O6+1 -> 45853 | Q6: =P6+1 -> 45854 | R6: =Q6+1 -> 45855 | S6: =R6+1 -> 45856 | T6: =S6+1 -> 45857 | U6: =T6+1 -> 45858 | V6: =U6+1 -> 45859 | W6: =V6+1 -> 45860 | ... BR6: =BQ6+1 -> 45907
A7: This row contains headers for the project schedule that follows below them. Navigate from B6 through BL 6 to hear the content. The first letter of each day of the week for the date above that heading, starts in cell I6 and continues through cell BL6. All project timeline charting is auto generated based on the start and end dates entered, using conditional formats. Do not modify content in cells within columns after column I starting with cell I7. | B7: Task | C7: Task Info | D7: Qty on Site | E7: Qty Completed | F7: Hours / Unit | G7: Total Hours | H7: Hours Remaining | I7: Progress | J7: Comments | K7: START | L7: END | N7: DAYS | O7: =LEFT(TEXT(O6,"ddd"),1) -> M | P7: =LEFT(TEXT(P6,"ddd"),1) -> T | Q7: =LEFT(TEXT(Q6,"ddd"),1) -> W | R7: =LEFT(TEXT(R6,"ddd"),1) -> T | S7: =LEFT(TEXT(S6,"ddd"),1) -> F | T7: =LEFT(TEXT(T6,"ddd"),1) -> S | U7: =LEFT(TEXT(U6,"ddd"),1) -> S | V7: =LEFT(TEXT(V6,"ddd"),1) -> M | ... BR7: =LEFT(TEXT(BR6,"ddd"),1) -> S
A8: Do not delete this row. This row is hidden to preserve a formula that is used to highlight the current day within the project schedule. | N8: =IF(OR(ISBLANK(task_start),ISBLANK(task_end)),"",task_end-task_start+1)
A9: The cell at right contains the Phase 2 sample title. You can create a new phase at any time within column B. This project schedule does not require phases. To remove the phase, simply delete the row. To create a new phase block in this row, enter a new Title in cell at right. To continue adding tasks to the phase above, enter a new row above this one and fill in the task data as in cell A9's instruction. Update the Phase details in cell at right based on cell A8's instruction. Continue navigating down column A cells to learn more. If you haven't added any new rows in this worksheet, you will find 2 additional sample phase blocks have been created for you in cells B20 and B26. Otherwise, navigate through column A cells to find the additional blocks. Repeat the instructions from cells A8 and A9 whenever you need to. | B9: SCOPE 1 | C9: Emergency Generator Distribution | G9: =SUM(G10:G16) -> 101 | H9: =SUM(H10:H16) -> 89 | I9: =(1-(H9/G9)) -> 0.11881188 | K9: 45839 | L9: 45901 | N9: =IF(OR(ISBLANK(task_start),ISBLANK(task_end)),"",task_end-task_start+1) -> 63
B10: Task 1.1 | C10: LV Switchboards | D10: 2 | E10: =SUM('Emergency Generator Dist'!E4,'Emergency Generator Dist'!E13) -> 0 | F10: 4 | G10: =D10*F10 -> 8 | H10: =(D10-E10)*F10 -> 8 | I10: =(1-(H10/G10)) -> 0 | K10: 45839 | L10: 45901 | N10: =IF(OR(ISBLANK(task_start),ISBLANK(task_end)),"",task_end-task_start+1) -> 63
B11: Task 1.2 | C11: LV Circuit Breakers Primary Injection | D11: 6 | E11: =SUM('Emergency Generator Dist'!E5,'Emergency Generator Dist'!E14) -> 0 | F11: 3 | G11: =D11*F11 -> 18 | H11: =(D11-E11)*F11 -> 18 | I11: =(1-(H11/G11)) -> 0 | K11: 45839 | L11: 45901
B12: Task 1.3 | C12: LV ATS' (Hi-Potential & DLRO) | D12: 7 | E12: =SUM('Emergency Generator Dist'!E7,'Emergency Generator Dist'!E16,'Emergency Generator Dist'!E23) -> 3 | F12: 4 | G12: =D12*F12 -> 28 | H12: =(D12-E12)*F12 -> 16 | I12: =(1-(H12/G12)) -> 0.42857143 | K12: 45839 | L12: 45901
B13: Task 1.4 | C13: LV Distribution Panels | D13: 3 | E13: =SUM('Emergency Generator Dist'!E8,'Emergency Generator Dist'!E17,'Emergency Generator Dist'!E22) -> 0 | F13: 4 | G13: =D13*F13 -> 12 | H13: =(D13-E13)*F13 -> 12 | I13: =(1-(H13/G13)) -> 0 | K13: 45839 | L13: 45901
B14: Task 1.5 | C14: LV Panelboards | D14: 26 | E14: =SUM('Emergency Generator Dist'!E9,'Emergency Generator Dist'!E18,'Emergency Generator Dist'!E24) -> 0 | F14: 1 | G14: =D14*F14 -> 26 | H14: =(D14-E14)*F14 -> 26 | I14: =(1-(H14/G14)) -> 0 | K14: 45839 | L14: 45901
B15: Task 1.6 | C15: LV MCB Secondary Injection | D15: 8 | E15: =SUM('Emergency Generator Dist'!E10,'Emergency Generator Dist'!E19,'Emergency Generator Dist'!E25) -> 0 | F15: 0.5 | G15: =D15*F15 -> 4 | H15: =(D15-E15)*F15 -> 4 | I15: =(1-(H15/G15)) -> 0 | K15: 45839 | L15: 45901
B16: Task 1.7 | C16: LV Dry-Type Transformer | D16: 4 | E16: =SUM('Emergency Generator Dist'!E11,'Emergency Generator Dist'!E20) -> 0 | F16: 1.25 | G16: =D16*F16 -> 5 | H16: =(D16-E16)*F16 -> 5 | I16: =(1-(H16/G16)) -> 0 | K16: 45839 | L16: 45901
A17: The cell at right contains the Phase 2 sample title. You can create a new phase at any time within column B. This project schedule does not require phases. To remove the phase, simply delete the row. To create a new phase block in this row, enter a new Title in cell at right. To continue adding tasks to the phase above, enter a new row above this one and fill in the task data as in cell A9's instruction. Update the Phase details in cell at right based on cell A8's instruction. Continue navigating down column A cells to learn more. If you haven't added any new rows in this worksheet, you will find 2 additional sample phase blocks have been created for you in cells B20 and B26. Otherwise, navigate through column A cells to find the additional blocks. Repeat the instructions from cells A8 and A9 whenever you need to. | B17: SCOPE 2 | C17: Datacenter Main Distribution | G17: =SUM(G18:G24) -> 85 | H17: =SUM(H18:H24) -> 85 | I17: =(1-(H17/G17)) -> 0 | K17: 45839 | L17: 45901 | N17: =IF(OR(ISBLANK(task_start),ISBLANK(task_end)),"",task_end-task_start+1) -> 63
B18: Task 1.1 | C18: LV Isolation-Bypass ATS' (Hi-Potential & DLRO) | D18: 2 | E18: ='Datacenter Distribution'!D4 -> 0 | F18: 4 | G18: =D18*F18 -> 8 | H18: =(D18-E18)*F18 -> 8 | I18: =(1-(H18/G18)) -> 0 | K18: 45839 | L18: 45901 | N18: =IF(OR(ISBLANK(task_start),ISBLANK(task_end)),"",task_end-task_start+1) -> 63
B19: Task 1.2 | C19: LV Distribution Boards | D19: 4 | E19: =SUM('Datacenter Distribution'!D5,'Datacenter Distribution'!D11) -> 0 | F19: 4 | G19: =D19*F19 -> 16 | H19: =(D19-E19)*F19 -> 16 | I19: =(1-(H19/G19)) -> 0 | K19: 45839 | L19: 45901
B20: Task 1.3 | C20: LV Circuit Breakers Primary Injection | D20: 10 | E20: =SUM('Datacenter Distribution'!D6,'Datacenter Distribution'!D12) -> 0 | F20: 3 | G20: =D20*F20 -> 30 | H20: =(D20-E20)*F20 -> 30 | I20: =(1-(H20/G20)) -> 0 | K20: 45839 | L20: 45901
B21: Task 1.4 | C21: LV Distribution Panels | D21: 2 | E21: ='Datacenter Distribution'!D7 -> 0 | F21: 4 | G21: =D21*F21 -> 8 | H21: =(D21-E21)*F21 -> 8 | I21: =(1-(H21/G21)) -> 0 | K21: 45839 | L21: 45901
B22: Task 1.5 | C22: LV Panelboards | D22: 1 | E22: ='Datacenter Distribution'!D8 -> 0 | F22: 1 | G22: =D22*F22 -> 1 | H22: =(D22-E22)*F22 -> 1 | I22: =(1-(H22/G22)) -> 0 | K22: 45839 | L22: 45901
B23: Task 1.6 | C23: LV Large Dry-Type Transformer | D23: 2 | E23: ='Datacenter Distribution'!D10 -> 0 | F23: 4 | G23: =D23*F23 -> 8 | H23: =(D23-E23)*F23 -> 8 | I23: =(1-(H23/G23)) -> 0 | K23: 45839 | L23: 45901
B24: Task 1.7 | C24: LV MCB Secondary Injection | D24: 28 | E24: ='Datacenter Distribution'!D13 -> 0 | F24: 0.5 | G24: =D24*F24 -> 14 | H24: =(D24-E24)*F24 -> 14 | I24: =(1-(H24/G24)) -> 0 | K24: 45839 | L24: 45901
A25: The cell at right contains the Phase 2 sample title. You can create a new phase at any time within column B. This project schedule does not require phases. To remove the phase, simply delete the row. To create a new phase block in this row, enter a new Title in cell at right. To continue adding tasks to the phase above, enter a new row above this one and fill in the task data as in cell A9's instruction. Update the Phase details in cell at right based on cell A8's instruction. Continue navigating down column A cells to learn more. If you haven't added any new rows in this worksheet, you will find 2 additional sample phase blocks have been created for you in cells B20 and B26. Otherwise, navigate through column A cells to find the additional blocks. Repeat the instructions from cells A8 and A9 whenever you need to. | B25: SCOPE 3 | C25: A1 Electrical Rooms | G25: =SUM(G26:G32) -> 292 | H25: =SUM(H26:H32) -> 154 | I25: =(1-(H25/G25)) -> 0.47260274 | K25: 45839 | L25: 45901 | N25: =IF(OR(ISBLANK(task_start),ISBLANK(task_end)),"",task_end-task_start+1) -> 63
B26: Task 1.1 | C26: Unit Substation LV Circuit Breakers (Primary Injection) | D26: =SUM('A1 Electrical Room'!B3,'A1 Electrical Room'!B10,'A1 Electrical Room'!B15,'A1 Electrical Room'!B18,'A1 Electrical Room'!B23,'A1 Electrical Room'!B29,'A1 Electrical Room'!B35) -> 46 | E26: =SUM('A1 Electrical Room'!E3,'A1 Electrical Room'!E10,'A1 Electrical Room'!E15,'A1 Electrical Room'!E18,'A1 Electrical Room'!E23,'A1 Electrical Room'!E29,'A1 Electrical Room'!E35) -> 46 | F26: 3 | G26: =D26*F26 -> 138 | H26: =(D26-E26)*F26 -> 0 | I26: =(1-(H26/G26)) -> 1 | K26: 45839 | L26: 45901 | N26: =IF(OR(ISBLANK(task_start),ISBLANK(task_end)),"",task_end-task_start+1) -> 63
B27: Task 1.2 | C27: LV Distribution Panelboards | D27: =SUM('A1 Electrical Room'!B4,'A1 Electrical Room'!B11,'A1 Electrical Room'!B30,'A1 Electrical Room'!B36) -> 11 | E27: =SUM('A1 Electrical Room'!E4,'A1 Electrical Room'!E11,'A1 Electrical Room'!E30,'A1 Electrical Room'!E36) -> 0 | F27: 4 | G27: =D27*F27 -> 44 | H27: =(D27-E27)*F27 -> 44 | I27: =(1-(H27/G27)) -> 0 | K27: 45839 | L27: 45901
B28: Task 1.3 | C28: LV Panelboards | D28: =SUM('A1 Electrical Room'!B5,'A1 Electrical Room'!B12,'A1 Electrical Room'!B19,'A1 Electrical Room'!B24,'A1 Electrical Room'!B31,'A1 Electrical Room'!B37) -> 49 | E28: =SUM('A1 Electrical Room'!E5,'A1 Electrical Room'!E12,'A1 Electrical Room'!E19,'A1 Electrical Room'!E24,'A1 Electrical Room'!E31,'A1 Electrical Room'!E37) -> 0 | F28: 1 | G28: =D28*F28 -> 49 | H28: =(D28-E28)*F28 -> 49 | I28: =(1-(H28/G28)) -> 0 | K28: 45839 | L28: 45901
B29: Task 1.4 | C29: LV MCB Secondary Injection | D29: =SUM('A1 Electrical Room'!B6,'A1 Electrical Room'!B13,'A1 Electrical Room'!B25,'A1 Electrical Room'!B32,'A1 Electrical Room'!B38) -> 38 | E29: =SUM('A1 Electrical Room'!E6,'A1 Electrical Room'!E13,'A1 Electrical Room'!E25,'A1 Electrical Room'!E32,'A1 Electrical Room'!E38) -> 0 | F29: 0.5 | G29: =D29*F29 -> 19 | H29: =(D29-E29)*F29 -> 19 | I29: =(1-(H29/G29)) -> 0 | K29: 45839 | L29: 45901
B30: Task 1.5 | C30: LV Dry-Type Transformer | D30: =SUM('A1 Electrical Room'!B33,'A1 Electrical Room'!B39) -> 6 | E30: =SUM('A1 Electrical Room'!E39,'A1 Electrical Room'!E33) -> 0 | F30: 1.25 | G30: =D30*F30 -> 7.5 | H30: =(D30-E30)*F30 -> 7.5 | I30: =(1-(H30/G30)) -> 0 | K30: 45839 | L30: 45901
B31: Task 1.6 | C31: LV Bus Duct | D31: =SUM('A1 Electrical Room'!B7,'A1 Electrical Room'!B16,'A1 Electrical Room'!B20,'A1 Electrical Room'!B26) -> 4 | E31: =SUM('A1 Electrical Room'!E7,'A1 Electrical Room'!E16,'A1 Electrical Room'!E20,'A1 Electrical Room'!E26) -> 0 | F31: 4 | G31: =D31*F31 -> 16 | H31: =(D31-E31)*F31 -> 16 | I31: =(1-(H31/G31)) -> 0 | K31: 45839 | L31: 45901
B32: Task 1.7 | C32: LV Bus Duct MCB's (Secondary Injection) | D32: =SUM('A1 Electrical Room'!B8,'A1 Electrical Room'!B21,'A1 Electrical Room'!B27) -> 37 | E32: =SUM('A1 Electrical Room'!E8,'A1 Electrical Room'!E21,'A1 Electrical Room'!E27) -> 0 | F32: 0.5 | G32: =D32*F32 -> 18.5 | H32: =(D32-E32)*F32 -> 18.5 | I32: =(1-(H32/G32)) -> 0 | K32: 45839 | L32: 45901
A33: Sample phase title block | B33: SCOPE 4 | C33: A2 Electrical Rooms | G33: =SUM(G34:G40) -> 221.75 | H33: =SUM(H34:H40) -> 120.25 | I33: =(1-(H33/G33)) -> 0.45772266 | K33: 45839 | L33: 45901 | N33: =IF(OR(ISBLANK(task_start),ISBLANK(task_end)),"",task_end-task_start+1) -> 63
B34: Task 1.1 | C34: Unit Substation LV Circuit Breakers (Primary Injection) | D34: =SUM('A2 Electrical Room'!B3,'A2 Electrical Room'!B9,'A2 Electrical Room'!B14,'A2 Electrical Room'!B19) -> 33 | E34: =SUM('A2 Electrical Room'!E3,'A2 Electrical Room'!E9,'A2 Electrical Room'!E14,'A2 Electrical Room'!E19) -> 33 | F34: 3 | G34: =D34*F34 -> 99 | H34: =(D34-E34)*F34 -> 0 | I34: =(1-(H34/G34)) -> 1 | K34: 45839 | L34: 45901 | N34: =IF(OR(ISBLANK(task_start),ISBLANK(task_end)),"",task_end-task_start+1) -> 63
B35: Task 1.2 | C35: LV Distribution Panelboards | D35: =SUM('A2 Electrical Room'!B4,'A2 Electrical Room'!B15,'A2 Electrical Room'!B20) -> 12 | E35: =SUM('A2 Electrical Room'!E4,'A2 Electrical Room'!E15,'A2 Electrical Room'!E20) -> 0 | F35: 4 | G35: =D35*F35 -> 48 | H35: =(D35-E35)*F35 -> 48 | I35: =(1-(H35/G35)) -> 0 | K35: 45839 | L35: 45901
B36: Task 1.3 | C36: LV Panelboards | D36: =SUM('A2 Electrical Room'!B5,'A2 Electrical Room'!B10,'A2 Electrical Room'!B16,'A2 Electrical Room'!B21) -> 43 | E36: =SUM('A2 Electrical Room'!E5,'A2 Electrical Room'!E10,'A2 Electrical Room'!E16,'A2 Electrical Room'!E21) -> 0 | F36: 1 | G36: =D36*F36 -> 43 | H36: =(D36-E36)*F36 -> 43 | I36: =(1-(H36/G36)) -> 0 | K36: 45839 | L36: 45901 | N36: =IF(OR(ISBLANK(task_start),ISBLANK(task_end)),"",task_end-task_start+1) -> 63
B37: Task 1.4 | C37: LV MCB Secondary Injection | D37: =SUM('A2 Electrical Room'!B6,'A2 Electrical Room'!B17,'A2 Electrical Room'!B22) -> 29 | E37: =SUM('A2 Electrical Room'!E6,'A2 Electrical Room'!E17,'A2 Electrical Room'!E22) -> 0 | F37: 0.5 | G37: =D37*F37 -> 14.5 | H37: =(D37-E37)*F37 -> 14.5 | I37: =(1-(H37/G37)) -> 0 | K37: 45839 | L37: 45901 | N37: =IF(OR(ISBLANK(task_start),ISBLANK(task_end)),"",task_end-task_start+1) -> 63
B38: Task 1.5 | C38: LV Dry-Type Transformer | D38: =SUM('A2 Electrical Room'!B7) -> 3 | E38: =SUM('A2 Electrical Room'!E7) -> 2 | F38: 1.25 | G38: =D38*F38 -> 3.75 | H38: =(D38-E38)*F38 -> 1.25 | I38: =(1-(H38/G38)) -> 0.66666667 | K38: 45839 | L38: 45901
B39: Task 1.6 | C39: LV Bus Duct | D39: =SUM('A2 Electrical Room'!B11,'A2 Electrical Room'!B23) -> 3 | E39: =SUM('A2 Electrical Room'!E11,'A2 Electrical Room'!E23) -> 0 | F39: 4 | G39: =D39*F39 -> 12 | H39: =(D39-E39)*F39 -> 12 | I39: =(1-(H39/G39)) -> 0 | K39: 45839 | L39: 45901 | N39: =IF(OR(ISBLANK(task_start),ISBLANK(task_end)),"",task_end-task_start+1) -> 63
B40: Task 1.7 | C40: LV Bus Duct MCB's (Secondary Injection) | D40: =SUM('A2 Electrical Room'!B12) -> 3 | E40: =SUM('A2 Electrical Room'!E12) -> 0 | F40: 0.5 | G40: =D40*F40 -> 1.5 | H40: =(D40-E40)*F40 -> 1.5 | I40: =(1-(H40/G40)) -> 0 | K40: 45839 | L40: 45901
B41: SCOPE 5 | C41: E Electrical Room | G41: =SUM(G42:G50) -> 709.7 | H41: =SUM(H42:H50) -> 338.35 | I41: =(1-(H41/G41)) -> 0.52324926 | K41: 45839 | L41: 45901
...

Sheet Emergency Generator Dist
C1: Emergency Generator Scope
B2: Qty Bid | C2: EQ Description | D2: Drawing | E2: QTY Complete | F2: Hrs/unit | G2: Total Hrs | H2: QTY Remain. | I2: Hours Remain | J2: Progress | K2: Notes
C3: 2.0 MW Generator & Distribution (Outdoor) | D3: 1FO-E601
B4: 1 | C4: 1F0EL-ESWB-01 (480Y/277V, 3000A) | E4: 0 | F4: 4 | G4: =B4*F4 -> 4 | H4: =B4-E4 -> 1 | I4: =H4*F4 -> 4 | J4: =(1-Table13478911[[#This Row],[Hours Remain]]/Table13478911[[#This Row],[Total Hrs]]) -> 0
B5: 3 | C5: LV Circuit Breakers Primary Injection | E5: 0 | F5: 3 | G5: =B5*F5 -> 9 | H5: =B5-E5 -> 3 | I5: =H5*F5 -> 9 | J5: =(1-Table13478911[[#This Row],[Hours Remain]]/Table13478911[[#This Row],[Total Hrs]]) -> 0
C6: Electrode Room Emergency Distribution
B7: 2 | C7: LV ATS' (Hi-Potential & DLRO) | E7: 1 | F7: 4 | G7: =B7*F7 -> 8 | H7: =B7-E7 -> 1 | I7: =H7*F7 -> 4 | J7: =(1-Table13478911[[#This Row],[Hours Remain]]/Table13478911[[#This Row],[Total Hrs]]) -> 0.5
B8: 1 | C8: LV Distribution Panel 1F0EL-EHDP-2 01 | E8: 0 | F8: 4 | G8: =B8*F8 -> 4 | H8: =B8-E8 -> 1 | I8: =H8*F8 -> 4 | J8: =(1-Table13478911[[#This Row],[Hours Remain]]/Table13478911[[#This Row],[Total Hrs]]) -> 0
B9: 8 | C9: LV Panelboards | E9: 0 | F9: 1 | G9: =B9*F9 -> 8 | H9: =B9-E9 -> 8 | I9: =H9*F9 -> 8 | J9: =(1-Table13478911[[#This Row],[Hours Remain]]/Table13478911[[#This Row],[Total Hrs]]) -> 0
B10: 3 | C10: LV MCB Secondary Injection | E10: 0 | F10: 0.5 | G10: =B10*F10 -> 1.5 | H10: =B10-E10 -> 3 | I10: =H10*F10 -> 1.5 | J10: =(1-Table13478911[[#This Row],[Hours Remain]]/Table13478911[[#This Row],[Total Hrs]]) -> 0
B11: 3 | C11: LV Dry-Type Transformer | E11: 0 | F11: 1.25 | G11: =B11*F11 -> 3.75 | H11: =B11-E11 -> 3 | I11: =H11*F11 -> 3.75 | J11: 0
C12: 1.5 MW Generator & Distribution (Outdoor)
B13: 1 | C13: 1F0AS-ESWB-02 (480Y/277V, 2500A) | E13: 0 | F13: 4 | G13: =B13*F13 -> 4 | H13: =B13-E13 -> 1 | I13: =H13*F13 -> 4 | J13: =(1-Table13478911[[#This Row],[Hours Remain]]/Table13478911[[#This Row],[Total Hrs]]) -> 0
B14: 3 | C14: LV Circuit Breakers Primary Injection | E14: 0 | F14: 3 | G14: =B14*F14 -> 9 | H14: =B14-E14 -> 3 | I14: =H14*F14 -> 9 | J14: =(1-Table13478911[[#This Row],[Hours Remain]]/Table13478911[[#This Row],[Total Hrs]]) -> 0
C15: A1 & A2 Electrical Room Emergency Distribution
B16: 2 | C16: LV ATS' (Hi-Potential & DLRO) | E16: 2 | F16: 4 | G16: =B16*F16 -> 8 | H16: =B16-E16 -> 0 | I16: =H16*F16 -> 0 | J16: =(1-Table13478911[[#This Row],[Hours Remain]]/Table13478911[[#This Row],[Total Hrs]]) -> 1
B17: 1 | C17: LV Distribution Panel 1F0AS-EHDP-2 02 | E17: 0 | F17: 4 | G17: =B17*F17 -> 4 | H17: =B17-E17 -> 1 | I17: =H17*F17 -> 4 | J17: =(1-Table13478911[[#This Row],[Hours Remain]]/Table13478911[[#This Row],[Total Hrs]]) -> 0
B18: 10 | C18: LV Panelboards | E18: 0 | F18: 1 | G18: =B18*F18 -> 10 | H18: =B18-E18 -> 10 | I18: =H18*F18 -> 10 | J18: =(1-Table13478911[[#This Row],[Hours Remain]]/Table13478911[[#This Row],[Total Hrs]]) -> 0
B19: 2 | C19: LV MCB Secondary Injection | E19: 0 | F19: 0.5 | G19: =B19*F19 -> 1 | H19: =B19-E19 -> 2 | I19: =H19*F19 -> 1 | J19: =(1-Table13478911[[#This Row],[Hours Remain]]/Table13478911[[#This Row],[Total Hrs]]) -> 0
B20: 1 | C20: LV Dry-Type Transformer | E20: 0 | F20: 1.25 | G20: =B20*F20 -> 1.25 | H20: =B20-E20 -> 1 | I20: =H20*F20 -> 1.25 | J20: 0
C21: F1 & F2 Electrical Room Emergency Distribution
B22: 1 | C22: LV Distribution Panel 1F0FO-EHDP-2 01 | E22: 0 | F22: 4 | G22: =B22*F22 -> 4 | H22: =B22-E22 -> 1 | I22: =H22*F22 -> 4 | J22: =(1-Table13478911[[#This Row],[Hours Remain]]/Table13478911[[#This Row],[Total Hrs]]) -> 0
B23: 3 | C23: LV ATS' (Hi-Potential & DLRO) | E23: 0 | F23: 4 | G23: =B23*F23 -> 12 | H23: =B23-E23 -> 3 | I23: =H23*F23 -> 12 | J23: =(1-Table13478911[[#This Row],[Hours Remain]]/Table13478911[[#This Row],[Total Hrs]]) -> 0
B24: 8 | C24: LV Panelboards | E24: 0 | F24: 1 | G24: =B24*F24 -> 8 | H24: =B24-E24 -> 8 | I24: =H24*F24 -> 8 | J24: =(1-Table13478911[[#This Row],[Hours Remain]]/Table13478911[[#This Row],[Total Hrs]]) -> 0
B25: 3 | C25: LV MCB Secondary Injection | E25: 0 | F25: 0.5 | G25: =B25*F25 -> 1.5 | H25: =B25-E25 -> 3 | I25: =H25*F25 -> 1.5 | J25: =(1-Table13478911[[#This Row],[Hours Remain]]/Table13478911[[#This Row],[Total Hrs]]) -> 0
B27: =SUM(B4:B25) -> 56 | C27: TOTALS | E27: =SUM(Table13478911[QTY Complete]) -> 3 | G27: =SUM(Table13478911[Total Hrs]) -> 101 | H27: =B27-E27 -> 53 | I27: =SUM(Table13478911[Hours Remain]) -> 89 | J27: =(1-(I27/G27)) -> 0.11881188
C31: LV Distribution Panel = <1000 Amps Hi-Potential
C32: LV Panelboard = >1000 Amps Insulation Resistance
C33: LV MCB Secondary Injection = >250 Amps

Sheet Datacenter Distribution
C1: Datacenter Distribution Scope
B2: Qty Bid | C2: EQ Description | D2: QTY Complete | E2: Hrs/unit | F2: Total Hrs | G2: QTY Remain. | H2: Hours Remain | I2: Progress | J2: Notes
C3: Electrical Single Line 1FO-E653
B4: 2 | C4: LV Isolation-Bypass ATS' (Hi-Potential & DLRO) | D4: 0 | E4: 4 | F4: =B4*E4 -> 8 | G4: =B4-D4 -> 2 | H4: =G4*E4 -> 8 | I4: =(1-Table134789118[[#This Row],[Hours Remain]]/Table134789118[[#This Row],[Total Hrs]]) -> 0
B5: 2 | C5: LV Distribution Boards | D5: 0 | E5: 4 | F5: =B5*E5 -> 8 | G5: =B5-D5 -> 2 | H5: =G5*E5 -> 8 | I5: =(1-Table134789118[[#This Row],[Hours Remain]]/Table134789118[[#This Row],[Total Hrs]]) -> 0
B6: 8 | C6: LV Circuit Breakers Primary Injection | D6: 0 | E6: 3 | F6: =B6*E6 -> 24 | G6: =B6-D6 -> 8 | H6: =G6*E6 -> 24 | I6: =(1-Table134789118[[#This Row],[Hours Remain]]/Table134789118[[#This Row],[Total Hrs]]) -> 0
B7: 2 | C7: LV Distribution Panels | D7: 0 | E7: 4 | F7: =B7*E7 -> 8 | G7: =B7-D7 -> 2 | H7: =G7*E7 -> 8 | I7: =(1-Table134789118[[#This Row],[Hours Remain]]/Table134789118[[#This Row],[Total Hrs]]) -> 0
B8: 1 | C8: LV Panelboards | D8: 0 | E8: 1 | F8: =B8*E8 -> 1 | G8: =B8-D8 -> 1 | H8: =G8*E8 -> 1 | I8: =(1-Table134789118[[#This Row],[Hours Remain]]/Table134789118[[#This Row],[Total Hrs]]) -> 0
C9: Electrical Single Line 1FO-E654
B10: 2 | C10: LV Large Dry-Type Transformer | D10: 0 | E10: 4 | F10: =B10*E10 -> 8 | G10: =B10-D10 -> 2 | H10: =G10*E10 -> 8 | I10: 0
B11: 2 | C11: LV Distribution Boards | D11: 0 | E11: 4 | F11: =B11*E11 -> 8 | G11: =B11-D11 -> 2 | H11: =G11*E11 -> 8 | I11: =(1-Table134789118[[#This Row],[Hours Remain]]/Table134789118[[#This Row],[Total Hrs]]) -> 0
B12: 2 | C12: LV Circuit Breakers Primary Injection | D12: 0 | E12: 3 | F12: =B12*E12 -> 6 | G12: =B12-D12 -> 2 | H12: =G12*E12 -> 6 | I12: =(1-Table134789118[[#This Row],[Hours Remain]]/Table134789118[[#This Row],[Total Hrs]]) -> 0
B13: 28 | C13: LV MCB Secondary Injection | D13: 0 | E13: 0.5 | F13: =B13*E13 -> 14 | G13: =B13-D13 -> 28 | H13: =G13*E13 -> 14 | I13: =(1-Table134789118[[#This Row],[Hours Remain]]/Table134789118[[#This Row],[Total Hrs]]) -> 0
B15: =SUM(B4:B13) -> 49 | C15: TOTALS | D15: =SUM(Table134789118[QTY Complete]) -> 0 | F15: =SUM(Table134789118[Total Hrs]) -> 85 | G15: =B15-D15 -> 49 | H15: =SUM(Table134789118[Hours Remain]) -> 85 | I15: =(1-(H15/F15)) -> 0
C20: LV Distribution Panel = <1000 Amps Hi-Potential
C21: LV Panelboard = >1000 Amps Insulation Resistance
C22: LV MCB Secondary Injection = >250 Amps

Sheet A1 Electrical Room
C1: A1 Elec Room Scope
B2: Qty Bid | C2: EQ Description | D2: Drawing | E2: QTY Complete | F2: Hrs/unit | G2: Total Hrs | H2: QTY Remain. | I2: Hours Remain | J2: Progress | K2: Notes
B3: 7 | C3: 1F0AS-SS-A-01 USS 600V Breakers (Primary) | D3: 1FO-E620 | E3: 7 | F3: 3 | G3: =B3*F3 -> 21 | H3: =B3-E3 -> 0 | I3: =H3*F3 -> 0 | J3: =(1-Table134789111213246[[#This Row],[Hours Remain]]/Table134789111213246[[#This Row],[Total Hrs]]) -> 1
B4: 3 | C4: LV Distribution Panelboards | E4: 0 | F4: 4 | G4: =B4*F4 -> 12 | H4: =B4-E4 -> 3 | I4: =H4*F4 -> 12 | J4: =(1-Table134789111213246[[#This Row],[Hours Remain]]/Table134789111213246[[#This Row],[Total Hrs]]) -> 0
B5: 6 | C5: LV Panelboards | E5: 0 | F5: 1 | G5: =B5*F5 -> 6 | H5: =B5-E5 -> 6 | I5: =H5*F5 -> 6 | J5: =(1-Table134789111213246[[#This Row],[Hours Remain]]/Table134789111213246[[#This Row],[Total Hrs]]) -> 0
B6: 15 | C6: LV MCB Secondary Injection | E6: 0 | F6: 0.5 | G6: =B6*F6 -> 7.5 | H6: =B6-E6 -> 15 | I6: =H6*F6 -> 7.5 | J6: =(1-Table134789111213246[[#This Row],[Hours Remain]]/Table134789111213246[[#This Row],[Total Hrs]]) -> 0
B7: 1 | C7: LV Bus Duct | E7: 0 | F7: 4 | G7: =B7*F7 -> 4 | H7: =B7-E7 -> 1 | I7: =H7*F7 -> 4 | J7: =(1-Table134789111213246[[#This Row],[Hours Remain]]/Table134789111213246[[#This Row],[Total Hrs]]) -> 0
B8: 9 | C8: LV Bus Duct MCB's (Secondary Injection) | E8: 0 | F8: 0.5 | G8: =B8*F8 -> 4.5 | H8: =B8-E8 -> 9 | I8: =H8*F8 -> 4.5 | J8: =(1-Table134789111213246[[#This Row],[Hours Remain]]/Table134789111213246[[#This Row],[Total Hrs]]) -> 0
B10: 9 | C10: 1F0AS-SS-A-02 USS 600V Breakers (Primary) | D10: 1FO-E621 | E10: 9 | F10: 3 | G10: =B10*F10 -> 27 | H10: =B10-E10 -> 0 | I10: =H10*F10 -> 0 | J10: =(1-Table134789111213246[[#This Row],[Hours Remain]]/Table134789111213246[[#This Row],[Total Hrs]]) -> 1
B11: 3 | C11: LV Distribution Panelboards | E11: 0 | F11: 4 | G11: =B11*F11 -> 12 | H11: =B11-E11 -> 3 | I11: =H11*F11 -> 12 | J11: =(1-Table134789111213246[[#This Row],[Hours Remain]]/Table134789111213246[[#This Row],[Total Hrs]]) -> 0
B12: 5 | C12: LV Panelboards | E12: 0 | F12: 1 | G12: =B12*F12 -> 5 | H12: =B12-E12 -> 5 | I12: =H12*F12 -> 5 | J12: =(1-Table134789111213246[[#This Row],[Hours Remain]]/Table134789111213246[[#This Row],[Total Hrs]]) -> 0
B13: 11 | C13: LV MCB Secondary Injection | E13: 0 | F13: 0.5 | G13: =B13*F13 -> 5.5 | H13: =B13-E13 -> 11 | I13: =H13*F13 -> 5.5 | J13: =(1-Table134789111213246[[#This Row],[Hours Remain]]/Table134789111213246[[#This Row],[Total Hrs]]) -> 0
B15: 4 | C15: 1F0AS-SS-B-01 USS 600V Breakers (Primary) | D15: 1FO-E624 | E15: 4 | F15: 3 | G15: =B15*F15 -> 12 | H15: =B15-E15 -> 0 | I15: =H15*F15 -> 0 | J15: =(1-Table134789111213246[[#This Row],[Hours Remain]]/Table134789111213246[[#This Row],[Total Hrs]]) -> 1
B16: 1 | C16: LV Bus Duct | E16: 0 | F16: 4 | G16: =B16*F16 -> 4 | H16: =B16-E16 -> 1 | I16: =H16*F16 -> 4 | J16: =(1-Table134789111213246[[#This Row],[Hours Remain]]/Table134789111213246[[#This Row],[Total Hrs]]) -> 0
B18: 4 | C18: 1F0AS-SS-B-02 USS 600V Breakers (Primary) | D18: 1FO-E625 | E18: 4 | F18: 3 | G18: =B18*F18 -> 12 | H18: =B18-E18 -> 0 | I18: =H18*F18 -> 0 | J18: =(1-Table134789111213246[[#This Row],[Hours Remain]]/Table134789111213246[[#This Row],[Total Hrs]]) -> 1
B19: 3 | C19: LV Panelboards | E19: 0 | F19: 1 | G19: =B19*F19 -> 3 | H19: =B19-E19 -> 3 | I19: =H19*F19 -> 3 | J19: =(1-Table134789111213246[[#This Row],[Hours Remain]]/Table134789111213246[[#This Row],[Total Hrs]]) -> 0
B20: 1 | C20: LV Bus Duct | E20: 0 | F20: 4 | G20: =B20*F20 -> 4 | H20: =B20-E20 -> 1 | I20: =H20*F20 -> 4 | J20: 0
B21: 5 | C21: LV Bus Duct MCB's (Secondary Injection) | E21: 0 | F21: 0.5 | G21: =B21*F21 -> 2.5 | H21: =B21-E21 -> 5 | I21: =H21*F21 -> 2.5 | J21: 0
B23: 4 | C23: 1F0AS-SS-B-03 USS 600V Breakers (Primary) | D23: 1FO-E626 | E23: 4 | F23: 3 | G23: =B23*F23 -> 12 | H23: =B23-E23 -> 0 | I23: =H23*F23 -> 0 | J23: =(1-Table134789111213246[[#This Row],[Hours Remain]]/Table134789111213246[[#This Row],[Total Hrs]]) -> 1
B24: 5 | C24: LV Panelboards | E24: 0 | F24: 1 | G24: =B24*F24 -> 5 | H24: =B24-E24 -> 5 | I24: =H24*F24 -> 5 | J24: =(1-Table134789111213246[[#This Row],[Hours Remain]]/Table134789111213246[[#This Row],[Total Hrs]]) -> 0
B25: 1 | C25: LV MCB Secondary Injection | E25: 0 | F25: 0.5 | G25: =B25*F25 -> 0.5 | H25: =B25-E25 -> 1 | I25: =H25*F25 -> 0.5 | J25: =(1-Table134789111213246[[#This Row],[Hours Remain]]/Table134789111213246[[#This Row],[Total Hrs]]) -> 0
B26: 1 | C26: LV Bus Duct | E26: 0 | F26: 4 | G26: =B26*F26 -> 4 | H26: =B26-E26 -> 1 | I26: =H26*F26 -> 4 | J26: =(1-Table134789111213246[[#This Row],[Hours Remain]]/Table134789111213246[[#This Row],[Total Hrs]]) -> 0
B27: 23 | C27: LV Bus Duct MCB's (Secondary Injection) | E27: 0 | F27: 0.5 | G27: =B27*F27 -> 11.5 | H27: =B27-E27 -> 23 | I27: =H27*F27 -> 11.5 | J27: =(1-Table134789111213246[[#This Row],[Hours Remain]]/Table134789111213246[[#This Row],[Total Hrs]]) -> 0
B29: 9 | C29: 1F0AS-SS-B-04 USS 600V Breakers (Primary) | D29: 1FO-E627 | E29: 9 | F29: 3 | G29: =B29*F29 -> 27 | H29: =B29-E29 -> 0 | I29: =H29*F29 -> 0 | J29: =(1-Table134789111213246[[#This Row],[Hours Remain]]/Table134789111213246[[#This Row],[Total Hrs]]) -> 1
B30: 2 | C30: LV Distribution Panelboards | E30: 0 | F30: 4 | G30: =B30*F30 -> 8 | H30: =B30-E30 -> 2 | I30: =H30*F30 -> 8 | J30: =(1-Table134789111213246[[#This Row],[Hours Remain]]/Table134789111213246[[#This Row],[Total Hrs]]) -> 0
B31: 11 | C31: LV Panelboards | E31: 0 | F31: 1 | G31: =B31*F31 -> 11 | H31: =B31-E31 -> 11 | I31: =H31*F31 -> 11 | J31: =(1-Table134789111213246[[#This Row],[Hours Remain]]/Table134789111213246[[#This Row],[Total Hrs]]) -> 0
B32: 8 | C32: LV MCB Secondary Injection | E32: 0 | F32: 0.5 | G32: =B32*F32 -> 4 | H32: =B32-E32 -> 8 | I32: =H32*F32 -> 4 | J32: =(1-Table134789111213246[[#This Row],[Hours Remain]]/Table134789111213246[[#This Row],[Total Hrs]]) -> 0
B33: 2 | C33: LV Dry-Type Transformer | E33: 0 | F33: 1.25 | G33: =B33*F33 -> 2.5 | H33: =B33-E33 -> 2 | I33: =H33*F33 -> 2.5 | J33: =(1-Table134789111213246[[#This Row],[Hours Remain]]/Table134789111213246[[#This Row],[Total Hrs]]) -> 0
B35: 9 | C35: 1F0AS-SS-B-05 USS 600V Breakers (Primary) | D35: 1FO-E628 | E35: 9 | F35: 3 | G35: =B35*F35 -> 27 | H35: =B35-E35 -> 0 | I35: =H35*F35 -> 0 | J35: =(1-Table134789111213246[[#This Row],[Hours Remain]]/Table134789111213246[[#This Row],[Total Hrs]]) -> 1
B36: 3 | C36: LV Distribution Panelboards | E36: 0 | F36: 4 | G36: =B36*F36 -> 12 | H36: =B36-E36 -> 3 | I36: =H36*F36 -> 12 | J36: =(1-Table134789111213246[[#This Row],[Hours Remain]]/Table134789111213246[[#This Row],[Total Hrs]]) -> 0
B37: 19 | C37: LV Panelboards | E37: 0 | F37: 1 | G37: =B37*F37 -> 19 | H37: =B37-E37 -> 19 | I37: =H37*F37 -> 19 | J37: =(1-Table134789111213246[[#This Row],[Hours Remain]]/Table134789111213246[[#This Row],[Total Hrs]]) -> 0
B38: 3 | C38: LV MCB Secondary Injection | E38: 0 | F38: 0.5 | G38: =B38*F38 -> 1.5 | H38: =B38-E38 -> 3 | I38: =H38*F38 -> 1.5 | J38: =(1-Table134789111213246[[#This Row],[Hours Remain]]/Table134789111213246[[#This Row],[Total Hrs]]) -> 0
B39: 4 | C39: LV Dry-Type Transformer | E39: 0 | F39: 1.25 | G39: =B39*F39 -> 5 | H39: =B39-E39 -> 4 | I39: =H39*F39 -> 5 | J39: =(1-Table134789111213246[[#This Row],[Hours Remain]]/Table134789111213246[[#This Row],[Total Hrs]]) -> 0
B41: =SUM(B3:B40) -> 191 | C41: TOTALS | E41: =SUM(E3:E40) -> 46 | F41: =SUM(F3:F40) -> 65.5 | G41: =SUM(G3:G39) -> 292 | H41: =B41-E41 -> 145 | I41: =SUM(I3:I40) -> 154 | J41: =(1-(I41/G41)) -> 0.47260274
C46: LV Distribution Panel = <1000 Amps Hi-Potential
C47: LV Panelboard = >1000 Amps Insulation Resistance
C48: LV MCB Secondary Injection = >250 Amps

Sheet A2 Electrical Room
C1: A2 Elec Room Scope
B2: Qty Bid | C2: EQ Description | D2: Drawing | E2: QTY Complete | F2: Hrs/unit | G2: Total Hrs | H2: QTY Remain. | I2: Hours Remain | J2: Progress | K2: Notes
B3: 9 | C3: 1F0AS-SS-C-01 USS 600V Breakers (Primary) | D3: 1FO-E629 | E3: 9 | F3: 3 | G3: =B3*F3 -> 27 | H3: =B3-E3 -> 0 | I3: =H3*F3 -> 0 | J3: =(1-Table13478911121324[[#This Row],[Hours Remain]]/Table13478911121324[[#This Row],[Total Hrs]]) -> 1
B4: 4 | C4: LV Distribution Panelboards | E4: 0 | F4: 4 | G4: =B4*F4 -> 16 | H4: =B4-E4 -> 4 | I4: =H4*F4 -> 16 | J4: =(1-Table13478911121324[[#This Row],[Hours Remain]]/Table13478911121324[[#This Row],[Total Hrs]]) -> 0
B5: 13 | C5: LV Panelboards | E5: 0 | F5: 1 | G5: =B5*F5 -> 13 | H5: =B5-E5 -> 13 | I5: =H5*F5 -> 13 | J5: =(1-Table13478911121324[[#This Row],[Hours Remain]]/Table13478911121324[[#This Row],[Total Hrs]]) -> 0
B6: 5 | C6: LV MCB Secondary Injection | E6: 0 | F6: 0.5 | G6: =B6*F6 -> 2.5 | H6: =B6-E6 -> 5 | I6: =H6*F6 -> 2.5 | J6: =(1-Table13478911121324[[#This Row],[Hours Remain]]/Table13478911121324[[#This Row],[Total Hrs]]) -> 0
B7: 3 | C7: LV Dry-Type Transformer | E7: 2 | F7: 1.25 | G7: =B7*F7 -> 3.75 | H7: =B7-E7 -> 1 | I7: =H7*F7 -> 1.25 | J7: =(1-Table13478911121324[[#This Row],[Hours Remain]]/Table13478911121324[[#This Row],[Total Hrs]]) -> 0.66666667
G8: =B8*F8 -> 0 | H8: =B8-E8 -> 0 | I8: =H8*F8 -> 0
B9: 5 | C9: 1F0AS-SS-C-02 USS 600V Breakers (Primary) | D9: 1FO-E630 | E9: 5 | F9: 3 | G9: =B9*F9 -> 15 | H9: =B9-E9 -> 0 | I9: =H9*F9 -> 0 | J9: =(1-Table13478911121324[[#This Row],[Hours Remain]]/Table13478911121324[[#This Row],[Total Hrs]]) -> 1
B10: 3 | C10: LV Panelboards | E10: 0 | F10: 1 | G10: =B10*F10 -> 3 | H10: =B10-E10 -> 3 | I10: =H10*F10 -> 3 | J10: =(1-Table13478911121324[[#This Row],[Hours Remain]]/Table13478911121324[[#This Row],[Total Hrs]]) -> 0
B11: 2 | C11: LV Bus Duct | E11: 0 | F11: 4 | G11: =B11*F11 -> 8 | H11: =B11-E11 -> 2 | I11: =H11*F11 -> 8 | J11: =(1-Table13478911121324[[#This Row],[Hours Remain]]/Table13478911121324[[#This Row],[Total Hrs]]) -> 0
B12: 3 | C12: LV Bus Duct MCB's (Secondary Injection) | E12: 0 | F12: 0.5 | G12: =B12*F12 -> 1.5 | H12: =B12-E12 -> 3 | I12: =H12*F12 -> 1.5 | J12: =(1-Table13478911121324[[#This Row],[Hours Remain]]/Table13478911121324[[#This Row],[Total Hrs]]) -> 0
G13: =B13*F13 -> 0 | H13: =B13-E13 -> 0 | I13: =H13*F13 -> 0
B14: 9 | C14: 1F0AS-SS-C-03 USS 600V Breakers (Primary) | D14: 1FO-E631 | E14: 9 | F14: 3 | G14: =B14*F14 -> 27 | H14: =B14-E14 -> 0 | I14: =H14*F14 -> 0 | J14: =(1-Table13478911121324[[#This Row],[Hours Remain]]/Table13478911121324[[#This Row],[Total Hrs]]) -> 1
B15: 6 | C15: LV Distribution Panelboards | E15: 0 | F15: 4 | G15: =B15*F15 -> 24 | H15: =B15-E15 -> 6 | I15: =H15*F15 -> 24 | J15: =(1-Table13478911121324[[#This Row],[Hours Remain]]/Table13478911121324[[#This Row],[Total Hrs]]) -> 0
B16: 23 | C16: LV Panelboards | E16: 0 | F16: 1 | G16: =B16*F16 -> 23 | H16: =B16-E16 -> 23 | I16: =H16*F16 -> 23 | J16: =(1-Table13478911121324[[#This Row],[Hours Remain]]/Table13478911121324[[#This Row],[Total Hrs]]) -> 0
B17: 21 | C17: LV MCB Secondary Injection | E17: 0 | F17: 0.5 | G17: =B17*F17 -> 10.5 | H17: =B17-E17 -> 21 | I17: =H17*F17 -> 10.5 | J17: =(1-Table13478911121324[[#This Row],[Hours Remain]]/Table13478911121324[[#This Row],[Total Hrs]]) -> 0
G18: =B18*F18 -> 0 | H18: =B18-E18 -> 0 | I18: =H18*F18 -> 0
B19: 10 | C19: 1F0AS-SS-C-04 USS 600V Breakers (Primary) | D19: 1FO-E632 | E19: 10 | F19: 3 | G19: =B19*F19 -> 30 | H19: =B19-E19 -> 0 | I19: =H19*F19 -> 0 | J19: =(1-Table13478911121324[[#This Row],[Hours Remain]]/Table13478911121324[[#This Row],[Total Hrs]]) -> 1
B20: 2 | C20: LV Distribution Panelboards | E20: 0 | F20: 4 | G20: =B20*F20 -> 8 | H20: =B20-E20 -> 2 | I20: =H20*F20 -> 8 | J20: =(1-Table13478911121324[[#This Row],[Hours Remain]]/Table13478911121324[[#This Row],[Total Hrs]]) -> 0
B21: 4 | C21: LV Panelboards | E21: 0 | F21: 1 | G21: =B21*F21 -> 4 | H21: =B21-E21 -> 4 | I21: =H21*F21 -> 4 | J21: =(1-Table13478911121324[[#This Row],[Hours Remain]]/Table13478911121324[[#This Row],[Total Hrs]]) -> 0
B22: 3 | C22: LV MCB Secondary Injection | E22: 0 | F22: 0.5 | G22: =B22*F22 -> 1.5 | H22: =B22-E22 -> 3 | I22: =H22*F22 -> 1.5 | J22: =(1-Table13478911121324[[#This Row],[Hours Remain]]/Table13478911121324[[#This Row],[Total Hrs]]) -> 0
B23: 1 | C23: LV Bus Duct | E23: 0 | F23: 4 | G23: =B23*F23 -> 4 | H23: =B23-E23 -> 1 | I23: =H23*F23 -> 4 | J23: =(1-Table13478911121324[[#This Row],[Hours Remain]]/Table13478911121324[[#This Row],[Total Hrs]]) -> 0
G24: =B24*F24 -> 0 | H24: =B24-E24 -> 0 | I24: =H24*F24 -> 0
B25: =SUM(B3:B24) -> 126 | C25: TOTALS | E25: =SUM(E3:E24) -> 35 | F25: =SUM(F3:F24) -> 39.25 | G25: =SUM(G3:G24) -> 221.75 | H25: =B25-E25 -> 91 | I25: =SUM(I3:I24) -> 120.25 | J25: =(1-(I25/G25)) -> 0.45772266
C30: LV Distribution Panel = <1000 Amps Hi-Potential
C31: LV Panelboard = >1000 Amps Insulation Resistance
C32: LV MCB Secondary Injection = >250 Amps

Sheet E Electrical Room
C1: E Elec Room Scope
B2: Qty Bid | C2: EQ Description | D2: Drawing | E2: QTY Complete | F2: Hrs/unit | G2: Total Hrs | H2: QTY Remain. | I2: Hours Remain | J2: Progress | K2: Notes
B3: 2 | C3: 1F0EL-SS-A-01 USS 600V Breakers (Primary) | D3: 1FO-E602 | E3: 2 | F3: 3 | G3: =B3*F3 -> 6 | H3: =B3-E3 -> 0 | I3: =H3*F3 -> 0 | J3: =(1-Table1347891112132[[#This Row],[Hours Remain]]/Table1347891112132[[#This Row],[Total Hrs]]) -> 1
B4: 2 | C4: LV Panelboards | E4: 1 | F4: 1 | G4: =B4*F4 -> 2 | H4: =B4-E4 -> 1 | I4: =H4*F4 -> 1 | J4: =(1-Table1347891112132[[#This Row],[Hours Remain]]/Table1347891112132[[#This Row],[Total Hrs]]) -> 0.5
B5: 4 | C5: LV MCB Secondary Injection | E5: 0 | F5: 0.5 | G5: =B5*F5 -> 2 | H5: =B5-E5 -> 4 | I5: =H5*F5 -> 2 | J5: =(1-Table1347891112132[[#This Row],[Hours Remain]]/Table1347891112132[[#This Row],[Total Hrs]]) -> 0
B6: 1 | C6: LV Bus Duct | E6: 1 | F6: 4 | G6: =B6*F6 -> 4 | H6: =B6-E6 -> 0 | I6: =H6*F6 -> 0 | J6: =(1-Table1347891112132[[#This Row],[Hours Remain]]/Table1347891112132[[#This Row],[Total Hrs]]) -> 1
B7: 31 | C7: LV Bus Duct MCB's (Secondary Injection) | E7: 0 | F7: 0.5 | G7: =B7*F7 -> 15.5 | H7: =B7-E7 -> 31 | I7: =H7*F7 -> 15.5 | J7: =(1-Table1347891112132[[#This Row],[Hours Remain]]/Table1347891112132[[#This Row],[Total Hrs]]) -> 0
B9: 2 | C9: 1F0EL-SS-A-02 USS 600V Breakers (Primary) | D9: 1FO-E603 | E9: 2 | F9: 3 | G9: =B9*F9 -> 6 | H9: =B9-E9 -> 0 | I9: =H9*F9 -> 0 | J9: =(1-Table1347891112132[[#This Row],[Hours Remain]]/Table1347891112132[[#This Row],[Total Hrs]]) -> 1
B10: 1 | C10: LV Bus Duct | E10: 0 | F10: 4 | G10: =B10*F10 -> 4 | H10: =B10-E10 -> 1 | I10: =H10*F10 -> 4 | J10: =(1-Table1347891112132[[#This Row],[Hours Remain]]/Table1347891112132[[#This Row],[Total Hrs]]) -> 0
B11: 33 | C11: LV Bus Duct MCB's (Secondary Injection) | E11: 0 | F11: 0.5 | G11: =B11*F11 -> 16.5 | H11: =B11-E11 -> 33 | I11: =H11*F11 -> 16.5 | J11: =(1-Table1347891112132[[#This Row],[Hours Remain]]/Table1347891112132[[#This Row],[Total Hrs]]) -> 0
B13: 5 | C13: 1F0EL-SS-A-03 USS 600V Breakers (Primary) | D13: 1FO-E604 | E13: 5 | F13: 3 | G13: =B13*F13 -> 15 | H13: =B13-E13 -> 0 | I13: =H13*F13 -> 0 | J13: =(1-Table1347891112132[[#This Row],[Hours Remain]]/Table1347891112132[[#This Row],[Total Hrs]]) -> 1
B14: 1 | C14: LV Bus Duct | E14: 0 | F14: 4 | G14: =B14*F14 -> 4 | H14: =B14-E14 -> 1 | I14: =H14*F14 -> 4 | J14: =(1-Table1347891112132[[#This Row],[Hours Remain]]/Table1347891112132[[#This Row],[Total Hrs]]) -> 0
B15: 22 | C15: LV Bus Duct MCB's (Secondary Injection) | E15: 0 | F15: 0.5 | G15: =B15*F15 -> 11 | H15: =B15-E15 -> 22 | I15: =H15*F15 -> 11 | J15: =(1-Table1347891112132[[#This Row],[Hours Remain]]/Table1347891112132[[#This Row],[Total Hrs]]) -> 0
B17: 2 | C17: 1F0EL-SS-A-04 USS 600V Breakers (Primary) | D17: 1FO-E605 | E17: 2 | F17: 3 | G17: =B17*F17 -> 6 | H17: =B17-E17 -> 0 | I17: =H17*F17 -> 0 | J17: =(1-Table1347891112132[[#This Row],[Hours Remain]]/Table1347891112132[[#This Row],[Total Hrs]]) -> 1
B18: 1 | C18: LV Bus Duct | E18: 0 | F18: 4 | G18: =B18*F18 -> 4 | H18: =B18-E18 -> 1 | I18: =H18*F18 -> 4 | J18: =(1-Table1347891112132[[#This Row],[Hours Remain]]/Table1347891112132[[#This Row],[Total Hrs]]) -> 0
B19: 18 | C19: LV Bus Duct MCB's (Secondary Injection) | E19: 0 | F19: 0.5 | G19: =B19*F19 -> 9 | H19: =B19-E19 -> 18 | I19: =H19*F19 -> 9 | J19: =(1-Table1347891112132[[#This Row],[Hours Remain]]/Table1347891112132[[#This Row],[Total Hrs]]) -> 0
B21: 5 | C21: 1F0EL-SS-B-01 USS 600V Breakers (Primary) | D21: 1FO-E607 | E21: 5 | F21: 3 | G21: =B21*F21 -> 15 | H21: =B21-E21 -> 0 | I21: =H21*F21 -> 0 | J21: =(1-Table1347891112132[[#This Row],[Hours Remain]]/Table1347891112132[[#This Row],[Total Hrs]]) -> 1
B22: 1 | C22: LV Distribution Panelboards | E22: 0 | F22: 4 | G22: =B22*F22 -> 4 | H22: =B22-E22 -> 1 | I22: =H22*F22 -> 4 | J22: =(1-Table1347891112132[[#This Row],[Hours Remain]]/Table1347891112132[[#This Row],[Total Hrs]]) -> 0
B23: 6 | C23: LV Panelboards | E23: 0 | F23: 1 | G23: =B23*F23 -> 6 | H23: =B23-E23 -> 6 | I23: =H23*F23 -> 6 | J23: =(1-Table1347891112132[[#This Row],[Hours Remain]]/Table1347891112132[[#This Row],[Total Hrs]]) -> 0
B24: 5 | C24: LV MCB Secondary Injection | E24: 0 | F24: 0.5 | G24: =B24*F24 -> 2.5 | H24: =B24-E24 -> 5 | I24: =H24*F24 -> 2.5 | J24: =(1-Table1347891112132[[#This Row],[Hours Remain]]/Table1347891112132[[#This Row],[Total Hrs]]) -> 0
B25: 2 | C25: LV Bus Duct | E25: 0 | F25: 4 | G25: =B25*F25 -> 8 | H25: =B25-E25 -> 2 | I25: =H25*F25 -> 8 | J25: =(1-Table1347891112132[[#This Row],[Hours Remain]]/Table1347891112132[[#This Row],[Total Hrs]]) -> 0
B26: 36 | C26: LV Bus Duct MCB's (Secondary Injection) | E26: 0 | F26: 0.5 | G26: =B26*F26 -> 18 | H26: =B26-E26 -> 36 | I26: =H26*F26 -> 18 | J26: =(1-Table1347891112132[[#This Row],[Hours Remain]]/Table1347891112132[[#This Row],[Total Hrs]]) -> 0
B28: 9 | C28: 1F0EL-SS-B-02 USS 600V Breakers (Primary) | D28: 1FO-E608 | E28: 9 | F28: 3 | G28: =B28*F28 -> 27 | H28: =B28-E28 -> 0 | I28: =H28*F28 -> 0 | J28: =(1-Table1347891112132[[#This Row],[Hours Remain]]/Table1347891112132[[#This Row],[Total Hrs]]) -> 1
B29: 5 | C29: LV Distribution Panelboards | E29: 5 | F29: 4 | G29: =B29*F29 -> 20 | H29: =B29-E29 -> 0 | I29: =H29*F29 -> 0 | J29: =(1-Table1347891112132[[#This Row],[Hours Remain]]/Table1347891112132[[#This Row],[Total Hrs]]) -> 1
B30: 10 | C30: LV Panelboards | E30: 10 | F30: 1 | G30: =B30*F30 -> 10 | H30: =B30-E30 -> 0 | I30: =H30*F30 -> 0 | J30: =(1-Table1347891112132[[#This Row],[Hours Remain]]/Table1347891112132[[#This Row],[Total Hrs]]) -> 1
B31: 14 | C31: LV MCB Secondary Injection | E31: 0 | F31: 0.5 | G31: =B31*F31 -> 7 | H31: =B31-E31 -> 14 | I31: =H31*F31 -> 7 | J31: =(1-Table1347891112132[[#This Row],[Hours Remain]]/Table1347891112132[[#This Row],[Total Hrs]]) -> 0
B32: 2 | C32: LV Dry-Type Transformer | E32: 2 | F32: 1.25 | G32: =B32*F32 -> 2.5 | H32: =B32-E32 -> 0 | I32: =H32*F32 -> 0 | J32: =(1-Table1347891112132[[#This Row],[Hours Remain]]/Table1347891112132[[#This Row],[Total Hrs]]) -> 1
B34: 9 | C34: 1F0EL-SS-B-03 USS 600V Breakers (Primary) | D34: 1FO-E609 | E34: 9 | F34: 3 | G34: =B34*F34 -> 27 | H34: =B34-E34 -> 0 | I34: =H34*F34 -> 0 | J34: =(1-Table1347891112132[[#This Row],[Hours Remain]]/Table1347891112132[[#This Row],[Total Hrs]]) -> 1
B35: 5 | C35: LV Distribution Panelboards | E35: 3 | F35: 4 | G35: =B35*F35 -> 20 | H35: =B35-E35 -> 2 | I35: =H35*F35 -> 8 | J35: =(1-Table1347891112132[[#This Row],[Hours Remain]]/Table1347891112132[[#This Row],[Total Hrs]]) -> 0.6
B36: 20 | C36: LV Panelboards | E36: 0 | F36: 1 | G36: =B36*F36 -> 20 | H36: =B36-E36 -> 20 | I36: =H36*F36 -> 20 | J36: =(1-Table1347891112132[[#This Row],[Hours Remain]]/Table1347891112132[[#This Row],[Total Hrs]]) -> 0
B37: 12 | C37: LV MCB Secondary Injection | E37: 0 | F37: 0.5 | G37: =B37*F37 -> 6 | H37: =B37-E37 -> 12 | I37: =H37*F37 -> 6 | J37: =(1-Table1347891112132[[#This Row],[Hours Remain]]/Table1347891112132[[#This Row],[Total Hrs]]) -> 0
B38: 6 | C38: LV Dry-Type Transformer | E38: 3 | F38: 1.25 | G38: =B38*F38 -> 7.5 | H38: =B38-E38 -> 3 | I38: =H38*F38 -> 3.75 | J38: =(1-Table1347891112132[[#This Row],[Hours Remain]]/Table1347891112132[[#This Row],[Total Hrs]]) -> 0.5
B40: 13 | C40: 1F0EL-SS-B-04 USS 600V Breakers (Primary) | D40: 1FO-E610 | E40: 13 | F40: 3 | G40: =B40*F40 -> 39 | H40: =B40-E40 -> 0 | I40: =H40*F40 -> 0 | J40: =(1-Table1347891112132[[#This Row],[Hours Remain]]/Table1347891112132[[#This Row],[Total Hrs]]) -> 1
B41: 6 | C41: LV Distribution Panelboards | E41: 2 | F41: 4 | G41: =B41*F41 -> 24 | H41: =B41-E41 -> 4 | I41: =H41*F41 -> 16 | J41: =(1-Table1347891112132[[#This Row],[Hours Remain]]/Table1347891112132[[#This Row],[Total Hrs]]) -> 0.33333333
B42: 6 | C42: LV Panelboards | E42: 0 | F42: 1 | G42: =B42*F42 -> 6 | H42: =B42-E42 -> 6 | I42: =H42*F42 -> 6 | J42: =(1-Table1347891112132[[#This Row],[Hours Remain]]/Table1347891112132[[#This Row],[Total Hrs]]) -> 0
B43: 23 | C43: LV MCB Secondary Injection | E43: 0 | F43: 0.5 | G43: =B43*F43 -> 11.5 | H43: =B43-E43 -> 23 | I43: =H43*F43 -> 11.5 | J43: =(1-Table1347891112132[[#This Row],[Hours Remain]]/Table1347891112132[[#This Row],[Total Hrs]]) -> 0
B45: 9 | C45: 1F0EL-SS-C-01 USS 600V Breakers (Primary) | D45: 1FO-E611 | E45: 9 | F45: 3 | G45: =B45*F45 -> 27 | H45: =B45-E45 -> 0 | I45: =H45*F45 -> 0 | J45: =(1-Table1347891112132[[#This Row],[Hours Remain]]/Table1347891112132[[#This Row],[Total Hrs]]) -> 1
B46: 5 | C46: LV Distribution Panelboards | E46: 4 | F46: 4 | G46: =B46*F46 -> 20 | H46: =B46-E46 -> 1 | I46: =H46*F46 -> 4 | J46: =(1-Table1347891112132[[#This Row],[Hours Remain]]/Table1347891112132[[#This Row],[Total Hrs]]) -> 0.8
B47: 13 | C47: LV Panelboards | E47: 2 | F47: 1 | G47: =B47*F47 -> 13 | H47: =B47-E47 -> 11 | I47: =H47*F47 -> 11 | J47: =(1-Table1347891112132[[#This Row],[Hours Remain]]/Table1347891112132[[#This Row],[Total Hrs]]) -> 0.15384615
B48: 8 | C48: LV MCB Secondary Injection | E48: 0 | F48: 0.5 | G48: =B48*F48 -> 4 | H48: =B48-E48 -> 8 | I48: =H48*F48 -> 4 | J48: =(1-Table1347891112132[[#This Row],[Hours Remain]]/Table1347891112132[[#This Row],[Total Hrs]]) -> 0
...

Sheet F1 Electrical Room
C1: F1 Elec Room Scope
B2: Qty Bid | C2: EQ Description | D2: Drawing | E2: QTY Complete | F2: Hrs/unit | G2: Total Hrs | H2: QTY Remain. | I2: Hours Remain | J2: Progress | K2: Notes
B3: 9 | C3: 1F0FO-SS-A-01 USS 600V Breakers (Primary) | D3: 1FO-E633 | E3: 9 | F3: 3 | G3: =B3*F3 -> 27 | H3: =B3-E3 -> 0 | I3: =H3*F3 -> 0 | J3: =(1-Table1347891112132457[[#This Row],[Hours Remain]]/Table1347891112132457[[#This Row],[Total Hrs]]) -> 1
C4: LV Distribution Panelboards | K4: Future
C5: LV MCB Secondary Injection | K5: Future
B7: 9 | C7: 1F0FO-SS-A-02 USS 600V Breakers (Primary) | D7: 1FO-E634 | E7: 9 | F7: 3 | G7: =B7*F7 -> 27 | H7: =B7-E7 -> 0 | I7: =H7*F7 -> 0 | J7: =(1-Table1347891112132457[[#This Row],[Hours Remain]]/Table1347891112132457[[#This Row],[Total Hrs]]) -> 1
B8: 1 | C8: LV Distribution Panelboards | E8: 0 | F8: 4 | G8: =B8*F8 -> 4 | H8: =B8-E8 -> 1 | I8: =H8*F8 -> 4 | J8: =(1-Table1347891112132457[[#This Row],[Hours Remain]]/Table1347891112132457[[#This Row],[Total Hrs]]) -> 0
B9: 9 | C9: LV Panelboards | E9: 0 | F9: 1 | G9: =B9*F9 -> 9 | H9: =B9-E9 -> 9 | I9: =H9*F9 -> 9 | J9: =(1-Table1347891112132457[[#This Row],[Hours Remain]]/Table1347891112132457[[#This Row],[Total Hrs]]) -> 0
B10: 5 | C10: LV MCB Secondary Injection | E10: 0 | F10: 0.5 | G10: =B10*F10 -> 2.5 | H10: =B10-E10 -> 5 | I10: =H10*F10 -> 2.5 | J10: =(1-Table1347891112132457[[#This Row],[Hours Remain]]/Table1347891112132457[[#This Row],[Total Hrs]]) -> 0
B12: 9 | C12: 1F0FO-SS-A-03 USS 600V Breakers (Primary) | D12: 1FO-E635 | E12: 9 | F12: 3 | G12: =B12*F12 -> 27 | H12: =B12-E12 -> 0 | I12: =H12*F12 -> 0 | J12: =(1-Table1347891112132457[[#This Row],[Hours Remain]]/Table1347891112132457[[#This Row],[Total Hrs]]) -> 1
B13: 3 | C13: LV Distribution Panelboards | E13: 0 | F13: 4 | G13: =B13*F13 -> 12 | H13: =B13-E13 -> 3 | I13: =H13*F13 -> 12 | J13: =(1-Table1347891112132457[[#This Row],[Hours Remain]]/Table1347891112132457[[#This Row],[Total Hrs]]) -> 0
B14: 13 | C14: LV Panelboards | E14: 0 | F14: 1 | G14: =B14*F14 -> 13 | H14: =B14-E14 -> 13 | I14: =H14*F14 -> 13 | J14: =(1-Table1347891112132457[[#This Row],[Hours Remain]]/Table1347891112132457[[#This Row],[Total Hrs]]) -> 0
B15: 5 | C15: LV MCB Secondary Injection | E15: 0 | F15: 0.5 | G15: =B15*F15 -> 2.5 | H15: =B15-E15 -> 5 | I15: =H15*F15 -> 2.5 | J15: =(1-Table1347891112132457[[#This Row],[Hours Remain]]/Table1347891112132457[[#This Row],[Total Hrs]]) -> 0
B16: 1 | C16: LV Dry-Type Transformer | E16: 0 | F16: 1.25 | G16: =B16*F16 -> 1.25 | H16: =B16-E16 -> 1 | I16: =H16*F16 -> 1.25 | J16: =(1-Table1347891112132457[[#This Row],[Hours Remain]]/Table1347891112132457[[#This Row],[Total Hrs]]) -> 0
B18: 9 | C18: 1F0FO-SS-A-04 USS 600V Breakers (Primary) | D18: 1FO-E636 | E18: 9 | F18: 3 | G18: =B18*F18 -> 27 | H18: =B18-E18 -> 0 | I18: =H18*F18 -> 0 | J18: =(1-Table1347891112132457[[#This Row],[Hours Remain]]/Table1347891112132457[[#This Row],[Total Hrs]]) -> 1
C19: LV Distribution Panelboards | K19: Future
C20: LV MCB Secondary Injection | K20: Future
B22: 9 | C22: 1F0FO-SS-A-05 USS 600V Breakers (Primary) | D22: 1FO-E637 | E22: 9 | F22: 3 | G22: 27 | H22: 9 | I22: 27 | J22: 0
C23: LV Distribution Panelboards | K23: Future
C24: LV MCB Secondary Injection | K24: Future
B26: 9 | C26: 1F0FO-SS-B-01 USS 600V Breakers (Primary) | D26: 1FO-E638 | E26: 9 | F26: 3 | G26: =B26*F26 -> 27 | H26: =B26-E26 -> 0 | I26: =H26*F26 -> 0 | J26: =(1-Table1347891112132457[[#This Row],[Hours Remain]]/Table1347891112132457[[#This Row],[Total Hrs]]) -> 1
B27: 2 | C27: LV Dry-Type Transformer | E27: 0 | F27: 1.25 | G27: =B27*F27 -> 2.5 | H27: =B27-E27 -> 2 | I27: =H27*F27 -> 2.5 | J27: =(1-Table1347891112132457[[#This Row],[Hours Remain]]/Table1347891112132457[[#This Row],[Total Hrs]]) -> 0
B29: 9 | C29: 1F0FO-SS-B-02 USS 600V Breakers (Primary) | D29: 1FO-E639 | E29: 9 | F29: 3 | G29: =B29*F29 -> 27 | H29: =B29-E29 -> 0 | I29: =H29*F29 -> 0 | J29: =(1-Table1347891112132457[[#This Row],[Hours Remain]]/Table1347891112132457[[#This Row],[Total Hrs]]) -> 1
B30: 3 | C30: LV Distribution Panelboards | E30: 0 | F30: 4 | G30: =B30*F30 -> 12 | H30: =B30-E30 -> 3 | I30: =H30*F30 -> 12 | J30: =(1-Table1347891112132457[[#This Row],[Hours Remain]]/Table1347891112132457[[#This Row],[Total Hrs]]) -> 0
B31: 6 | C31: LV MCB Secondary Injection | E31: 0 | F31: 0.5 | G31: =B31*F31 -> 3 | H31: =B31-E31 -> 6 | I31: =H31*F31 -> 3 | J31: =(1-Table1347891112132457[[#This Row],[Hours Remain]]/Table1347891112132457[[#This Row],[Total Hrs]]) -> 0
B33: 9 | C33: 1F0FO-SS-B-03 USS 600V Breakers (Primary) | D33: 1FO-E640 | E33: 9 | F33: 3 | G33: =B33*F33 -> 27 | H33: =B33-E33 -> 0 | I33: =H33*F33 -> 0 | J33: =(1-Table1347891112132457[[#This Row],[Hours Remain]]/Table1347891112132457[[#This Row],[Total Hrs]]) -> 1
C34: LV Distribution Panelboards | K34: Future
C35: LV MCB Secondary Injection | K35: Future
B37: 9 | C37: 1F0FO-SS-B-04 USS 600V Breakers (Primary) | D37: 1FO-E641 | E37: 9 | F37: 3 | G37: =B37*F37 -> 27 | H37: =B37-E37 -> 0 | I37: =H37*F37 -> 0 | J37: =(1-Table1347891112132457[[#This Row],[Hours Remain]]/Table1347891112132457[[#This Row],[Total Hrs]]) -> 1
C38: LV Distribution Panelboards | K38: Future
C39: LV MCB Secondary Injection | K39: Future
B41: 9 | C41: 1F0FO-SS-B-05 USS 600V Breakers (Primary) | D41: 1FO-E642 | E41: 9 | F41: 3 | G41: 27 | H41: 9 | I41: 27 | J41: 0
C42: LV Distribution Panelboards | K42: Future
C43: LV MCB Secondary Injection | K43: Future
B45: =SUM(B3:B44) -> 138 | C45: TOTALS | E45: =SUM(E3:E44) -> 90 | F45: =SUM(F3:F44) -> 48 | G45: =SUM(G3:G44) -> 331.75 | H45: =B45-E45 -> 48 | I45: =SUM(I3:I44) -> 115.75 | J45: =(1-(I45/G45)) -> 0.65109269
C48: LV Distribution Panel = <1000 Amps Hi-Potential
C49: LV Panelboard = >1000 Amps Insulation Resistance
C50: LV MCB Secondary Injection = >250 Amps

Sheet F2 Eletrical Room
C1: F2 Elec Room Scope
B2: Qty Bid | C2: EQ Description | D2: Drawing | E2: QTY Complete | F2: Hrs/unit | G2: Total Hrs | H2: QTY Remain. | I2: Hours Remain | J2: Progress | K2: Notes
B3: 9 | C3: 1F0FO-SS-C-01 USS 600V Breakers (Primary) | D3: 1FO-E643 | E3: 9 | F3: 3 | G3: =B3*F3 -> 27 | H3: =B3-E3 -> 0 | I3: =H3*F3 -> 0 | J3: =(1-Table13478911121324573[[#This Row],[Hours Remain]]/Table13478911121324573[[#This Row],[Total Hrs]]) -> 1
B4: 3 | C4: LV Distribution Panelboards | E4: 0 | F4: 4 | G4: =B4*F4 -> 12 | H4: =B4-E4 -> 3 | I4: =H4*F4 -> 12 | J4: 0
B5: 9 | C5: LV Panelboards | E5: 0 | F5: 1 | G5: =B5*F5 -> 9 | H5: =B5-E5 -> 9 | I5: =H5*F5 -> 9 | J5: 0
B6: 6 | C6: LV MCB Secondary Injection | E6: 0 | F6: 0.5 | G6: =B6*F6 -> 3 | H6: =B6-E6 -> 6 | I6: =H6*F6 -> 3 | J6: 0
B7: 2 | C7: LV Dry-Type Transformer | E7: 0 | F7: 1.25 | G7: =B7*F7 -> 2.5 | H7: =B7-E7 -> 2 | I7: =H7*F7 -> 2.5 | J7: 0
G8: =B8*F8 -> 0
B9: 13 | C9: 1F0FO-SS-C-02 USS 600V Breakers (Primary) | D9: 1FO-E644 | E9: 13 | F9: 3 | G9: =B9*F9 -> 39 | H9: =B9-E9 -> 0 | I9: =H9*F9 -> 0 | J9: =(1-Table13478911121324573[[#This Row],[Hours Remain]]/Table13478911121324573[[#This Row],[Total Hrs]]) -> 1
B10: 3 | C10: LV Distribution Panelboards | E10: 0 | F10: 4 | G10: =B10*F10 -> 12 | H10: =B10-E10 -> 3 | I10: =H10*F10 -> 12 | J10: =(1-Table13478911121324573[[#This Row],[Hours Remain]]/Table13478911121324573[[#This Row],[Total Hrs]]) -> 0
B11: 9 | C11: LV Panelboards | E11: 0 | F11: 1 | G11: =B11*F11 -> 9 | H11: =B11-E11 -> 9 | I11: =H11*F11 -> 9 | J11: =(1-Table13478911121324573[[#This Row],[Hours Remain]]/Table13478911121324573[[#This Row],[Total Hrs]]) -> 0
B12: 8 | C12: LV MCB Secondary Injection | E12: 0 | F12: 0.5 | G12: =B12*F12 -> 4 | H12: =B12-E12 -> 8 | I12: =H12*F12 -> 4 | J12: =(1-Table13478911121324573[[#This Row],[Hours Remain]]/Table13478911121324573[[#This Row],[Total Hrs]]) -> 0
G13: =B13*F13 -> 0
B14: 9 | C14: 1F0FO-SS-C-03 USS 600V Breakers (Primary) | D14: 1FO-E645 | E14: 9 | F14: 3 | G14: =B14*F14 -> 27 | H14: =B14-E14 -> 0 | I14: =H14*F14 -> 0 | J14: =(1-Table13478911121324573[[#This Row],[Hours Remain]]/Table13478911121324573[[#This Row],[Total Hrs]]) -> 1
B15: 4 | C15: LV Distribution Panelboards | E15: 0 | F15: 4 | G15: =B15*F15 -> 16 | H15: 4 | I15: =H15*F15 -> 16 | J15: 0
B16: 20 | C16: LV MCB Secondary Injection | E16: 0 | F16: 0.5 | G16: =B16*F16 -> 10 | H16: 20 | I16: =H16*F16 -> 10 | J16: 0
G17: =B17*F17 -> 0
B18: 9 | C18: 1F0FO-SS-C-04 USS 600V Breakers (Primary) | D18: 1FO-E646 | E18: 9 | F18: 3 | G18: =B18*F18 -> 27 | H18: =B18-E18 -> 0 | I18: =H18*F18 -> 0 | J18: =(1-Table13478911121324573[[#This Row],[Hours Remain]]/Table13478911121324573[[#This Row],[Total Hrs]]) -> 1
B19: 1 | C19: LV Distribution Panelboards | E19: 0 | F19: 4 | G19: =B19*F19 -> 4 | H19: =B19-E19 -> 1 | I19: =H19*F19 -> 4 | J19: 0
B20: 5 | C20: LV Panelboards | E20: 0 | F20: 1 | G20: =B20*F20 -> 5 | H20: =B20-E20 -> 5 | I20: =H20*F20 -> 5 | J20: 0
B21: 11 | C21: LV MCB Secondary Injection | E21: 0 | F21: 0.5 | G21: =B21*F21 -> 5.5 | H21: =B21-E21 -> 11 | I21: =H21*F21 -> 5.5 | J21: 0
G22: =B22*F22 -> 0
B23: 9 | C23: 1F0FO-SS-D-01 USS 600V Breakers (Primary) | D23: 1FO-E647 | E23: 9 | F23: 3 | G23: =B23*F23 -> 27 | H23: =B23-E23 -> 0 | I23: =H23*F23 -> 0 | J23: =(1-Table13478911121324573[[#This Row],[Hours Remain]]/Table13478911121324573[[#This Row],[Total Hrs]]) -> 1
B24: 4 | C24: LV Distribution Panelboards | E24: 0 | F24: 4 | G24: =B24*F24 -> 16 | H24: 4 | I24: =H24*F24 -> 16 | J24: 0
B25: 20 | C25: LV MCB Secondary Injection | E25: 0 | F25: 0.5 | G25: =B25*F25 -> 10 | H25: 20 | I25: =H25*F25 -> 10 | J25: 0
G26: =B26*F26 -> 0
B27: 9 | C27: 1F0FO-SS-D-02 USS 600V Breakers (Primary) | D27: 1FO-E648 | E27: 9 | F27: 3 | G27: =B27*F27 -> 27 | H27: =B27-E27 -> 0 | I27: =H27*F27 -> 0 | J27: =(1-Table13478911121324573[[#This Row],[Hours Remain]]/Table13478911121324573[[#This Row],[Total Hrs]]) -> 1
B28: 4 | C28: LV Distribution Panelboards | E28: 0 | F28: 4 | G28: =B28*F28 -> 16 | H28: 4 | I28: 16 | J28: 0
B29: 18 | C29: LV MCB Secondary Injection | E29: 0 | F29: 0.5 | G29: =B29*F29 -> 9 | H29: 20 | I29: 10 | J29: 0
G30: =B30*F30 -> 0
B31: 9 | C31: 1F0FO-SS-D-03 USS 600V Breakers (Primary) | D31: 1FO-E649 | E31: 9 | F31: 3 | G31: =B31*F31 -> 27 | H31: =B31-E31 -> 0 | I31: =H31*F31 -> 0 | J31: =(1-Table13478911121324573[[#This Row],[Hours Remain]]/Table13478911121324573[[#This Row],[Total Hrs]]) -> 1
B32: 4 | C32: LV Distribution Panelboards | E32: 0 | F32: 4 | G32: =B32*F32 -> 16 | H32: 4 | I32: 16 | J32: 0
B33: 16 | C33: LV MCB Secondary Injection | E33: 0 | F33: 0.5 | G33: =B33*F33 -> 8 | H33: 20 | I33: 10 | J33: 0
G34: =B34*F34 -> 0
B35: 9 | C35: 1F0FO-SS-D-04 USS 600V Breakers (Primary) | E35: 9 | F35: 3 | G35: =B35*F35 -> 27 | H35: =B35-E35 -> 0 | I35: =H35*F35 -> 0 | J35: =(1-Table13478911121324573[[#This Row],[Hours Remain]]/Table13478911121324573[[#This Row],[Total Hrs]]) -> 1
B36: 4 | C36: LV Distribution Panelboards | E36: 0 | F36: 4 | G36: =B36*F36 -> 16 | H36: =B36-E36 -> 4 | I36: =H36*F36 -> 16 | J36: 0
B37: 15 | C37: LV MCB Secondary Injection | E37: 0 | F37: 0.5 | G37: =B37*F37 -> 7.5 | H37: =B37-E37 -> 15 | I37: =H37*F37 -> 7.5 | J37: 0
B39: =SUM(B3:B37) -> 242 | C39: TOTALS | E39: =SUM(E3:E37) -> 76 | F39: =SUM(F3:F37) -> 64.25 | G39: =SUM(G3:G37) -> 418.5 | H39: =B39-E39 -> 166 | I39: =SUM(I3:I37) -> 193.5 | J39: =(1-(I39/G39)) -> 0.53763441
C43: LV Distribution Panel = <1000 Amps Hi-Potential
C44: LV Panelboard = >1000 Amps Insulation Resistance
...

Sheet RESA MV Breaker Test Results
CV1: www.resapower.com
A7: MV BREAKER TEST RESULT SUMMARY | CP7: TF-03 Rev.8
A9: JOB NUMBER: | S9: 559082 | AE9: DATE: | AS9: 45678 | BG9: TESTING STANDARD | CN9: P | CQ9: ACCEPTANCE TEST
A10: CLIENT NAME: | S10: STURGEON ELECTRIC | AE10: TESTED BY: | AS10: AP/TD | CQ10: MAINTENANCE TEST
A11: SITE/LOCATION: | S11: TPG CAT MODERNIZATION | AE11: APPROVED BY: | AS11: J. SWENSON | CQ11: PROOF TEST
A12: BREAKER NAMEPLATE DATA
